2019-09-11 13:06:15,310 - INFO - Бот запускается.
2019-09-11 13:06:25,189 - INFO - Вызван /start
2019-09-11 13:06:32,169 - INFO - Вызвана /planet
2019-09-11 13:06:52,399 - INFO - Вызвана /planet
2019-09-11 13:08:07,933 - INFO - Received signal 2 (SIGINT), stopping...
2019-09-11 13:08:16,547 - INFO - Бот запускается.
2019-09-11 13:08:20,034 - INFO - Вызван /start
2019-09-11 13:08:27,713 - INFO - Вызвана /planet
2019-09-11 13:08:37,364 - INFO - Вызвана /planet
2019-09-11 13:09:48,563 - INFO - Received signal 2 (SIGINT), stopping...
2019-09-11 13:10:03,529 - INFO - Бот запускается.
2019-09-11 13:10:12,479 - INFO - Вызвана /planet
2019-09-11 13:10:29,319 - INFO - Вызвана /planet
2019-09-11 13:16:27,305 - INFO - Received signal 2 (SIGINT), stopping...
2019-09-11 13:16:37,509 - INFO - Бот запускается.
2019-09-11 13:16:43,062 - INFO - Вызван /start
2019-09-11 13:16:52,633 - INFO - Вызвана /planet
2019-09-11 13:17:00,146 - INFO - Вызвана /planet
2019-09-11 13:17:06,195 - INFO - Вызвана /planet
2019-09-11 13:17:25,603 - INFO - Вызвана /planet
2019-09-11 13:18:41,676 - INFO - Received signal 2 (SIGINT), stopping...
2019-09-11 13:18:49,646 - INFO - Бот запускается.
2019-09-11 13:18:55,338 - INFO - Вызвана /planet
2019-09-11 13:21:44,798 - INFO - Received signal 2 (SIGINT), stopping...
2019-09-11 13:21:50,730 - INFO - Бот запускается.
2019-09-11 13:21:58,408 - INFO - Вызвана /planet
2019-09-11 13:22:21,113 - INFO - Вызвана /planet
2019-09-11 13:22:21,113 - ERROR - No error handlers are registered, logging exception.
Traceback (most recent call last):
  File "/Library/Frameworks/Python.framework/Versions/3.7/lib/python3.7/site-packages/telegram/ext/dispatcher.py", line 372, in process_update
    handler.handle_update(update, self, check, context)
  File "/Library/Frameworks/Python.framework/Versions/3.7/lib/python3.7/site-packages/telegram/ext/handler.py", line 120, in handle_update
    return self.callback(dispatcher.bot, update, **optional_args)
  File "bot.py", line 21, in check_the_sign
    message = update.message.text
AttributeError: 'NoneType' object has no attribute 'text'
2019-09-11 13:22:45,738 - INFO - Вызвана /planet
2019-09-11 13:22:56,018 - INFO - Вызвана /planet
2019-09-11 13:23:05,611 - INFO - Вызвана /planet
2019-09-11 13:25:43,126 - INFO - Received signal 2 (SIGINT), stopping...
2019-09-11 13:25:51,693 - INFO - Бот запускается.
2019-09-11 13:25:52,446 - INFO - Вызван /start
2019-09-11 13:26:04,304 - INFO - Вызвана /planet
2019-09-11 13:26:13,563 - INFO - Вызвана /planet
2019-09-11 13:46:33,973 - INFO - Вызван /start
2019-09-11 13:46:53,773 - INFO - Вызвана /planet
2019-09-11 13:47:09,461 - INFO - Вызвана /planet
2019-09-11 14:11:11,800 - INFO - Вызван /start
2019-09-11 14:39:06,027 - INFO - Received signal 2 (SIGINT), stopping...
2019-09-11 14:39:16,216 - INFO - Бот запускается.
2019-09-11 14:48:37,270 - INFO - Вызван /start
2019-09-11 14:48:48,329 - INFO - Вызвана /planet
2019-09-11 17:57:07,424 - WARNING - Retrying (Retry(total=2, connect=None, read=None, redirect=None)) after connection broken by 'NewConnectionError('<telegram.vendor.ptb_urllib3.urllib3.contrib.socks.SOCKSHTTPSConnection object at 0x10eefaef0>: Failed to establish a new connection: [Errno 8] nodename nor servname provided, or not known')': /bot882471193:AAE1dy0MNzGmh9E8wjahsdDDhNZ_LjU5e3I/getUpdates
2019-09-11 17:57:07,427 - WARNING - Retrying (Retry(total=1, connect=None, read=None, redirect=None)) after connection broken by 'NewConnectionError('<telegram.vendor.ptb_urllib3.urllib3.contrib.socks.SOCKSHTTPSConnection object at 0x10eefaf60>: Failed to establish a new connection: [Errno 8] nodename nor servname provided, or not known')': /bot882471193:AAE1dy0MNzGmh9E8wjahsdDDhNZ_LjU5e3I/getUpdates
2019-09-11 17:57:07,428 - WARNING - Retrying (Retry(total=0, connect=None, read=None, redirect=None)) after connection broken by 'NewConnectionError('<telegram.vendor.ptb_urllib3.urllib3.contrib.socks.SOCKSHTTPSConnection object at 0x10eefae80>: Failed to establish a new connection: [Errno 8] nodename nor servname provided, or not known')': /bot882471193:AAE1dy0MNzGmh9E8wjahsdDDhNZ_LjU5e3I/getUpdates
2019-09-11 17:57:09,416 - ERROR - Error while getting Updates: urllib3 HTTPError SOCKSHTTPSConnectionPool(host='api.telegram.org', port=443): Max retries exceeded with url: /bot882471193:AAE1dy0MNzGmh9E8wjahsdDDhNZ_LjU5e3I/getUpdates (Caused by NewConnectionError('<telegram.vendor.ptb_urllib3.urllib3.contrib.socks.SOCKSHTTPSConnection object at 0x10ef25080>: Failed to establish a new connection: [Errno 8] nodename nor servname provided, or not known'))
2019-09-11 17:57:09,417 - ERROR - No error handlers are registered, logging exception.
Traceback (most recent call last):
  File "/Library/Frameworks/Python.framework/Versions/3.7/lib/python3.7/site-packages/telegram/vendor/ptb_urllib3/urllib3/contrib/socks.py", line 88, in _new_conn
    **extra_kw
  File "/Library/Frameworks/Python.framework/Versions/3.7/lib/python3.7/site-packages/socks.py", line 180, in create_connection
    for r in socket.getaddrinfo(proxy_addr, proxy_port, 0, socket.SOCK_STREAM):
  File "/Library/Frameworks/Python.framework/Versions/3.7/lib/python3.7/socket.py", line 748, in getaddrinfo
    for res in _socket.getaddrinfo(host, port, family, type, proto, flags):
socket.gaierror: [Errno 8] nodename nor servname provided, or not known

During handling of the above exception, another exception occurred:

Traceback (most recent call last):
  File "/Library/Frameworks/Python.framework/Versions/3.7/lib/python3.7/site-packages/telegram/vendor/ptb_urllib3/urllib3/connectionpool.py", line 617, in urlopen
    chunked=chunked)
  File "/Library/Frameworks/Python.framework/Versions/3.7/lib/python3.7/site-packages/telegram/vendor/ptb_urllib3/urllib3/connectionpool.py", line 360, in _make_request
    self._validate_conn(conn)
  File "/Library/Frameworks/Python.framework/Versions/3.7/lib/python3.7/site-packages/telegram/vendor/ptb_urllib3/urllib3/connectionpool.py", line 857, in _validate_conn
    super(HTTPSConnectionPool, self)._validate_conn(conn)
  File "/Library/Frameworks/Python.framework/Versions/3.7/lib/python3.7/site-packages/telegram/vendor/ptb_urllib3/urllib3/connectionpool.py", line 289, in _validate_conn
    conn.connect()
  File "/Library/Frameworks/Python.framework/Versions/3.7/lib/python3.7/site-packages/telegram/vendor/ptb_urllib3/urllib3/connection.py", line 284, in connect
    conn = self._new_conn()
  File "/Library/Frameworks/Python.framework/Versions/3.7/lib/python3.7/site-packages/telegram/vendor/ptb_urllib3/urllib3/contrib/socks.py", line 120, in _new_conn
    self, "Failed to establish a new connection: %s" % e)
telegram.vendor.ptb_urllib3.urllib3.exceptions.NewConnectionError: <telegram.vendor.ptb_urllib3.urllib3.contrib.socks.SOCKSHTTPSConnection object at 0x10ef25080>: Failed to establish a new connection: [Errno 8] nodename nor servname provided, or not known

During handling of the above exception, another exception occurred:

Traceback (most recent call last):
  File "/Library/Frameworks/Python.framework/Versions/3.7/lib/python3.7/site-packages/telegram/utils/request.py", line 218, in _request_wrapper
    resp = self._con_pool.request(*args, **kwargs)
  File "/Library/Frameworks/Python.framework/Versions/3.7/lib/python3.7/site-packages/telegram/vendor/ptb_urllib3/urllib3/request.py", line 70, in request
    **urlopen_kw)
  File "/Library/Frameworks/Python.framework/Versions/3.7/lib/python3.7/site-packages/telegram/vendor/ptb_urllib3/urllib3/request.py", line 148, in request_encode_body
    return self.urlopen(method, url, **extra_kw)
  File "/Library/Frameworks/Python.framework/Versions/3.7/lib/python3.7/site-packages/telegram/vendor/ptb_urllib3/urllib3/poolmanager.py", line 244, in urlopen
    response = conn.urlopen(method, u.request_uri, **kw)
  File "/Library/Frameworks/Python.framework/Versions/3.7/lib/python3.7/site-packages/telegram/vendor/ptb_urllib3/urllib3/connectionpool.py", line 695, in urlopen
    **response_kw)
  File "/Library/Frameworks/Python.framework/Versions/3.7/lib/python3.7/site-packages/telegram/vendor/ptb_urllib3/urllib3/connectionpool.py", line 695, in urlopen
    **response_kw)
  File "/Library/Frameworks/Python.framework/Versions/3.7/lib/python3.7/site-packages/telegram/vendor/ptb_urllib3/urllib3/connectionpool.py", line 695, in urlopen
    **response_kw)
  File "/Library/Frameworks/Python.framework/Versions/3.7/lib/python3.7/site-packages/telegram/vendor/ptb_urllib3/urllib3/connectionpool.py", line 666, in urlopen
    _stacktrace=sys.exc_info()[2])
  File "/Library/Frameworks/Python.framework/Versions/3.7/lib/python3.7/site-packages/telegram/vendor/ptb_urllib3/urllib3/util/retry.py", line 376, in increment
    raise MaxRetryError(_pool, url, error or ResponseError(cause))
telegram.vendor.ptb_urllib3.urllib3.exceptions.MaxRetryError: SOCKSHTTPSConnectionPool(host='api.telegram.org', port=443): Max retries exceeded with url: /bot882471193:AAE1dy0MNzGmh9E8wjahsdDDhNZ_LjU5e3I/getUpdates (Caused by NewConnectionError('<telegram.vendor.ptb_urllib3.urllib3.contrib.socks.SOCKSHTTPSConnection object at 0x10ef25080>: Failed to establish a new connection: [Errno 8] nodename nor servname provided, or not known'))

During handling of the above exception, another exception occurred:

Traceback (most recent call last):
  File "/Library/Frameworks/Python.framework/Versions/3.7/lib/python3.7/site-packages/telegram/ext/updater.py", line 332, in _network_loop_retry
    if not action_cb():
  File "/Library/Frameworks/Python.framework/Versions/3.7/lib/python3.7/site-packages/telegram/ext/updater.py", line 293, in polling_action_cb
    allowed_updates=allowed_updates)
  File "/Library/Frameworks/Python.framework/Versions/3.7/lib/python3.7/site-packages/telegram/bot.py", line 66, in decorator
    result = func(self, *args, **kwargs)
  File "/Library/Frameworks/Python.framework/Versions/3.7/lib/python3.7/site-packages/telegram/bot.py", line 1982, in get_updates
    result = self._request.post(url, data, timeout=float(read_latency) + float(timeout))
  File "/Library/Frameworks/Python.framework/Versions/3.7/lib/python3.7/site-packages/telegram/utils/request.py", line 327, in post
    **urlopen_kwargs)
  File "/Library/Frameworks/Python.framework/Versions/3.7/lib/python3.7/site-packages/telegram/utils/request.py", line 224, in _request_wrapper
    raise NetworkError('urllib3 HTTPError {0}'.format(error))
telegram.error.NetworkError: urllib3 HTTPError SOCKSHTTPSConnectionPool(host='api.telegram.org', port=443): Max retries exceeded with url: /bot882471193:AAE1dy0MNzGmh9E8wjahsdDDhNZ_LjU5e3I/getUpdates (Caused by NewConnectionError('<telegram.vendor.ptb_urllib3.urllib3.contrib.socks.SOCKSHTTPSConnection object at 0x10ef25080>: Failed to establish a new connection: [Errno 8] nodename nor servname provided, or not known'))
2019-09-11 17:57:10,419 - WARNING - Retrying (Retry(total=2, connect=None, read=None, redirect=None)) after connection broken by 'NewConnectionError('<telegram.vendor.ptb_urllib3.urllib3.contrib.socks.SOCKSHTTPSConnection object at 0x10f0063c8>: Failed to establish a new connection: [Errno 8] nodename nor servname provided, or not known')': /bot882471193:AAE1dy0MNzGmh9E8wjahsdDDhNZ_LjU5e3I/getUpdates
2019-09-11 17:57:10,969 - WARNING - Retrying (Retry(total=1, connect=None, read=None, redirect=None)) after connection broken by 'NewConnectionError('<telegram.vendor.ptb_urllib3.urllib3.contrib.socks.SOCKSHTTPSConnection object at 0x10eefada0>: Failed to establish a new connection: [Errno 8] nodename nor servname provided, or not known')': /bot882471193:AAE1dy0MNzGmh9E8wjahsdDDhNZ_LjU5e3I/getUpdates
2019-09-11 17:57:10,982 - WARNING - Retrying (Retry(total=0, connect=None, read=None, redirect=None)) after connection broken by 'NewConnectionError('<telegram.vendor.ptb_urllib3.urllib3.contrib.socks.SOCKSHTTPSConnection object at 0x10eefab38>: Failed to establish a new connection: [Errno 8] nodename nor servname provided, or not known')': /bot882471193:AAE1dy0MNzGmh9E8wjahsdDDhNZ_LjU5e3I/getUpdates
2019-09-11 17:57:10,986 - ERROR - Error while getting Updates: urllib3 HTTPError SOCKSHTTPSConnectionPool(host='api.telegram.org', port=443): Max retries exceeded with url: /bot882471193:AAE1dy0MNzGmh9E8wjahsdDDhNZ_LjU5e3I/getUpdates (Caused by NewConnectionError('<telegram.vendor.ptb_urllib3.urllib3.contrib.socks.SOCKSHTTPSConnection object at 0x10ef25b38>: Failed to establish a new connection: [Errno 8] nodename nor servname provided, or not known'))
2019-09-11 17:57:10,987 - ERROR - No error handlers are registered, logging exception.
Traceback (most recent call last):
  File "/Library/Frameworks/Python.framework/Versions/3.7/lib/python3.7/site-packages/telegram/vendor/ptb_urllib3/urllib3/contrib/socks.py", line 88, in _new_conn
    **extra_kw
  File "/Library/Frameworks/Python.framework/Versions/3.7/lib/python3.7/site-packages/socks.py", line 180, in create_connection
    for r in socket.getaddrinfo(proxy_addr, proxy_port, 0, socket.SOCK_STREAM):
  File "/Library/Frameworks/Python.framework/Versions/3.7/lib/python3.7/socket.py", line 748, in getaddrinfo
    for res in _socket.getaddrinfo(host, port, family, type, proto, flags):
socket.gaierror: [Errno 8] nodename nor servname provided, or not known

During handling of the above exception, another exception occurred:

Traceback (most recent call last):
  File "/Library/Frameworks/Python.framework/Versions/3.7/lib/python3.7/site-packages/telegram/vendor/ptb_urllib3/urllib3/connectionpool.py", line 617, in urlopen
    chunked=chunked)
  File "/Library/Frameworks/Python.framework/Versions/3.7/lib/python3.7/site-packages/telegram/vendor/ptb_urllib3/urllib3/connectionpool.py", line 360, in _make_request
    self._validate_conn(conn)
  File "/Library/Frameworks/Python.framework/Versions/3.7/lib/python3.7/site-packages/telegram/vendor/ptb_urllib3/urllib3/connectionpool.py", line 857, in _validate_conn
    super(HTTPSConnectionPool, self)._validate_conn(conn)
  File "/Library/Frameworks/Python.framework/Versions/3.7/lib/python3.7/site-packages/telegram/vendor/ptb_urllib3/urllib3/connectionpool.py", line 289, in _validate_conn
    conn.connect()
  File "/Library/Frameworks/Python.framework/Versions/3.7/lib/python3.7/site-packages/telegram/vendor/ptb_urllib3/urllib3/connection.py", line 284, in connect
    conn = self._new_conn()
  File "/Library/Frameworks/Python.framework/Versions/3.7/lib/python3.7/site-packages/telegram/vendor/ptb_urllib3/urllib3/contrib/socks.py", line 120, in _new_conn
    self, "Failed to establish a new connection: %s" % e)
telegram.vendor.ptb_urllib3.urllib3.exceptions.NewConnectionError: <telegram.vendor.ptb_urllib3.urllib3.contrib.socks.SOCKSHTTPSConnection object at 0x10ef25b38>: Failed to establish a new connection: [Errno 8] nodename nor servname provided, or not known

During handling of the above exception, another exception occurred:

Traceback (most recent call last):
  File "/Library/Frameworks/Python.framework/Versions/3.7/lib/python3.7/site-packages/telegram/utils/request.py", line 218, in _request_wrapper
    resp = self._con_pool.request(*args, **kwargs)
  File "/Library/Frameworks/Python.framework/Versions/3.7/lib/python3.7/site-packages/telegram/vendor/ptb_urllib3/urllib3/request.py", line 70, in request
    **urlopen_kw)
  File "/Library/Frameworks/Python.framework/Versions/3.7/lib/python3.7/site-packages/telegram/vendor/ptb_urllib3/urllib3/request.py", line 148, in request_encode_body
    return self.urlopen(method, url, **extra_kw)
  File "/Library/Frameworks/Python.framework/Versions/3.7/lib/python3.7/site-packages/telegram/vendor/ptb_urllib3/urllib3/poolmanager.py", line 244, in urlopen
    response = conn.urlopen(method, u.request_uri, **kw)
  File "/Library/Frameworks/Python.framework/Versions/3.7/lib/python3.7/site-packages/telegram/vendor/ptb_urllib3/urllib3/connectionpool.py", line 695, in urlopen
    **response_kw)
  File "/Library/Frameworks/Python.framework/Versions/3.7/lib/python3.7/site-packages/telegram/vendor/ptb_urllib3/urllib3/connectionpool.py", line 695, in urlopen
    **response_kw)
  File "/Library/Frameworks/Python.framework/Versions/3.7/lib/python3.7/site-packages/telegram/vendor/ptb_urllib3/urllib3/connectionpool.py", line 695, in urlopen
    **response_kw)
  File "/Library/Frameworks/Python.framework/Versions/3.7/lib/python3.7/site-packages/telegram/vendor/ptb_urllib3/urllib3/connectionpool.py", line 666, in urlopen
    _stacktrace=sys.exc_info()[2])
  File "/Library/Frameworks/Python.framework/Versions/3.7/lib/python3.7/site-packages/telegram/vendor/ptb_urllib3/urllib3/util/retry.py", line 376, in increment
    raise MaxRetryError(_pool, url, error or ResponseError(cause))
telegram.vendor.ptb_urllib3.urllib3.exceptions.MaxRetryError: SOCKSHTTPSConnectionPool(host='api.telegram.org', port=443): Max retries exceeded with url: /bot882471193:AAE1dy0MNzGmh9E8wjahsdDDhNZ_LjU5e3I/getUpdates (Caused by NewConnectionError('<telegram.vendor.ptb_urllib3.urllib3.contrib.socks.SOCKSHTTPSConnection object at 0x10ef25b38>: Failed to establish a new connection: [Errno 8] nodename nor servname provided, or not known'))

During handling of the above exception, another exception occurred:

Traceback (most recent call last):
  File "/Library/Frameworks/Python.framework/Versions/3.7/lib/python3.7/site-packages/telegram/ext/updater.py", line 332, in _network_loop_retry
    if not action_cb():
  File "/Library/Frameworks/Python.framework/Versions/3.7/lib/python3.7/site-packages/telegram/ext/updater.py", line 293, in polling_action_cb
    allowed_updates=allowed_updates)
  File "/Library/Frameworks/Python.framework/Versions/3.7/lib/python3.7/site-packages/telegram/bot.py", line 66, in decorator
    result = func(self, *args, **kwargs)
  File "/Library/Frameworks/Python.framework/Versions/3.7/lib/python3.7/site-packages/telegram/bot.py", line 1982, in get_updates
    result = self._request.post(url, data, timeout=float(read_latency) + float(timeout))
  File "/Library/Frameworks/Python.framework/Versions/3.7/lib/python3.7/site-packages/telegram/utils/request.py", line 327, in post
    **urlopen_kwargs)
  File "/Library/Frameworks/Python.framework/Versions/3.7/lib/python3.7/site-packages/telegram/utils/request.py", line 224, in _request_wrapper
    raise NetworkError('urllib3 HTTPError {0}'.format(error))
telegram.error.NetworkError: urllib3 HTTPError SOCKSHTTPSConnectionPool(host='api.telegram.org', port=443): Max retries exceeded with url: /bot882471193:AAE1dy0MNzGmh9E8wjahsdDDhNZ_LjU5e3I/getUpdates (Caused by NewConnectionError('<telegram.vendor.ptb_urllib3.urllib3.contrib.socks.SOCKSHTTPSConnection object at 0x10ef25b38>: Failed to establish a new connection: [Errno 8] nodename nor servname provided, or not known'))
2019-09-11 17:57:14,040 - INFO - Вызвана /planet
2019-09-11 18:37:45,854 - WARNING - Retrying (Retry(total=2, connect=None, read=None, redirect=None)) after connection broken by 'NewConnectionError('<telegram.vendor.ptb_urllib3.urllib3.contrib.socks.SOCKSHTTPSConnection object at 0x10f0064a8>: Failed to establish a new connection: [Errno 8] nodename nor servname provided, or not known')': /bot882471193:AAE1dy0MNzGmh9E8wjahsdDDhNZ_LjU5e3I/getUpdates
2019-09-11 18:37:45,981 - WARNING - Retrying (Retry(total=1, connect=None, read=None, redirect=None)) after connection broken by 'NewConnectionError('<telegram.vendor.ptb_urllib3.urllib3.contrib.socks.SOCKSHTTPSConnection object at 0x10f006c50>: Failed to establish a new connection: [Errno 8] nodename nor servname provided, or not known')': /bot882471193:AAE1dy0MNzGmh9E8wjahsdDDhNZ_LjU5e3I/getUpdates
2019-09-11 18:37:45,984 - WARNING - Retrying (Retry(total=0, connect=None, read=None, redirect=None)) after connection broken by 'NewConnectionError('<telegram.vendor.ptb_urllib3.urllib3.contrib.socks.SOCKSHTTPSConnection object at 0x10f0066a0>: Failed to establish a new connection: [Errno 8] nodename nor servname provided, or not known')': /bot882471193:AAE1dy0MNzGmh9E8wjahsdDDhNZ_LjU5e3I/getUpdates
2019-09-11 18:37:45,985 - ERROR - Error while getting Updates: urllib3 HTTPError SOCKSHTTPSConnectionPool(host='api.telegram.org', port=443): Max retries exceeded with url: /bot882471193:AAE1dy0MNzGmh9E8wjahsdDDhNZ_LjU5e3I/getUpdates (Caused by NewConnectionError('<telegram.vendor.ptb_urllib3.urllib3.contrib.socks.SOCKSHTTPSConnection object at 0x10f006c18>: Failed to establish a new connection: [Errno 8] nodename nor servname provided, or not known'))
2019-09-11 18:37:46,026 - ERROR - No error handlers are registered, logging exception.
Traceback (most recent call last):
  File "/Library/Frameworks/Python.framework/Versions/3.7/lib/python3.7/site-packages/telegram/vendor/ptb_urllib3/urllib3/contrib/socks.py", line 88, in _new_conn
    **extra_kw
  File "/Library/Frameworks/Python.framework/Versions/3.7/lib/python3.7/site-packages/socks.py", line 180, in create_connection
    for r in socket.getaddrinfo(proxy_addr, proxy_port, 0, socket.SOCK_STREAM):
  File "/Library/Frameworks/Python.framework/Versions/3.7/lib/python3.7/socket.py", line 748, in getaddrinfo
    for res in _socket.getaddrinfo(host, port, family, type, proto, flags):
socket.gaierror: [Errno 8] nodename nor servname provided, or not known

During handling of the above exception, another exception occurred:

Traceback (most recent call last):
  File "/Library/Frameworks/Python.framework/Versions/3.7/lib/python3.7/site-packages/telegram/vendor/ptb_urllib3/urllib3/connectionpool.py", line 617, in urlopen
    chunked=chunked)
  File "/Library/Frameworks/Python.framework/Versions/3.7/lib/python3.7/site-packages/telegram/vendor/ptb_urllib3/urllib3/connectionpool.py", line 360, in _make_request
    self._validate_conn(conn)
  File "/Library/Frameworks/Python.framework/Versions/3.7/lib/python3.7/site-packages/telegram/vendor/ptb_urllib3/urllib3/connectionpool.py", line 857, in _validate_conn
    super(HTTPSConnectionPool, self)._validate_conn(conn)
  File "/Library/Frameworks/Python.framework/Versions/3.7/lib/python3.7/site-packages/telegram/vendor/ptb_urllib3/urllib3/connectionpool.py", line 289, in _validate_conn
    conn.connect()
  File "/Library/Frameworks/Python.framework/Versions/3.7/lib/python3.7/site-packages/telegram/vendor/ptb_urllib3/urllib3/connection.py", line 284, in connect
    conn = self._new_conn()
  File "/Library/Frameworks/Python.framework/Versions/3.7/lib/python3.7/site-packages/telegram/vendor/ptb_urllib3/urllib3/contrib/socks.py", line 120, in _new_conn
    self, "Failed to establish a new connection: %s" % e)
telegram.vendor.ptb_urllib3.urllib3.exceptions.NewConnectionError: <telegram.vendor.ptb_urllib3.urllib3.contrib.socks.SOCKSHTTPSConnection object at 0x10f006c18>: Failed to establish a new connection: [Errno 8] nodename nor servname provided, or not known

During handling of the above exception, another exception occurred:

Traceback (most recent call last):
  File "/Library/Frameworks/Python.framework/Versions/3.7/lib/python3.7/site-packages/telegram/utils/request.py", line 218, in _request_wrapper
    resp = self._con_pool.request(*args, **kwargs)
  File "/Library/Frameworks/Python.framework/Versions/3.7/lib/python3.7/site-packages/telegram/vendor/ptb_urllib3/urllib3/request.py", line 70, in request
    **urlopen_kw)
  File "/Library/Frameworks/Python.framework/Versions/3.7/lib/python3.7/site-packages/telegram/vendor/ptb_urllib3/urllib3/request.py", line 148, in request_encode_body
    return self.urlopen(method, url, **extra_kw)
  File "/Library/Frameworks/Python.framework/Versions/3.7/lib/python3.7/site-packages/telegram/vendor/ptb_urllib3/urllib3/poolmanager.py", line 244, in urlopen
    response = conn.urlopen(method, u.request_uri, **kw)
  File "/Library/Frameworks/Python.framework/Versions/3.7/lib/python3.7/site-packages/telegram/vendor/ptb_urllib3/urllib3/connectionpool.py", line 695, in urlopen
    **response_kw)
  File "/Library/Frameworks/Python.framework/Versions/3.7/lib/python3.7/site-packages/telegram/vendor/ptb_urllib3/urllib3/connectionpool.py", line 695, in urlopen
    **response_kw)
  File "/Library/Frameworks/Python.framework/Versions/3.7/lib/python3.7/site-packages/telegram/vendor/ptb_urllib3/urllib3/connectionpool.py", line 695, in urlopen
    **response_kw)
  File "/Library/Frameworks/Python.framework/Versions/3.7/lib/python3.7/site-packages/telegram/vendor/ptb_urllib3/urllib3/connectionpool.py", line 666, in urlopen
    _stacktrace=sys.exc_info()[2])
  File "/Library/Frameworks/Python.framework/Versions/3.7/lib/python3.7/site-packages/telegram/vendor/ptb_urllib3/urllib3/util/retry.py", line 376, in increment
    raise MaxRetryError(_pool, url, error or ResponseError(cause))
telegram.vendor.ptb_urllib3.urllib3.exceptions.MaxRetryError: SOCKSHTTPSConnectionPool(host='api.telegram.org', port=443): Max retries exceeded with url: /bot882471193:AAE1dy0MNzGmh9E8wjahsdDDhNZ_LjU5e3I/getUpdates (Caused by NewConnectionError('<telegram.vendor.ptb_urllib3.urllib3.contrib.socks.SOCKSHTTPSConnection object at 0x10f006c18>: Failed to establish a new connection: [Errno 8] nodename nor servname provided, or not known'))

During handling of the above exception, another exception occurred:

Traceback (most recent call last):
  File "/Library/Frameworks/Python.framework/Versions/3.7/lib/python3.7/site-packages/telegram/ext/updater.py", line 332, in _network_loop_retry
    if not action_cb():
  File "/Library/Frameworks/Python.framework/Versions/3.7/lib/python3.7/site-packages/telegram/ext/updater.py", line 293, in polling_action_cb
    allowed_updates=allowed_updates)
  File "/Library/Frameworks/Python.framework/Versions/3.7/lib/python3.7/site-packages/telegram/bot.py", line 66, in decorator
    result = func(self, *args, **kwargs)
  File "/Library/Frameworks/Python.framework/Versions/3.7/lib/python3.7/site-packages/telegram/bot.py", line 1982, in get_updates
    result = self._request.post(url, data, timeout=float(read_latency) + float(timeout))
  File "/Library/Frameworks/Python.framework/Versions/3.7/lib/python3.7/site-packages/telegram/utils/request.py", line 327, in post
    **urlopen_kwargs)
  File "/Library/Frameworks/Python.framework/Versions/3.7/lib/python3.7/site-packages/telegram/utils/request.py", line 224, in _request_wrapper
    raise NetworkError('urllib3 HTTPError {0}'.format(error))
telegram.error.NetworkError: urllib3 HTTPError SOCKSHTTPSConnectionPool(host='api.telegram.org', port=443): Max retries exceeded with url: /bot882471193:AAE1dy0MNzGmh9E8wjahsdDDhNZ_LjU5e3I/getUpdates (Caused by NewConnectionError('<telegram.vendor.ptb_urllib3.urllib3.contrib.socks.SOCKSHTTPSConnection object at 0x10f006c18>: Failed to establish a new connection: [Errno 8] nodename nor servname provided, or not known'))
2019-09-11 18:38:32,300 - INFO - Вызван /start
2019-09-11 18:38:32,328 - ERROR - No error handlers are registered, logging exception.
Traceback (most recent call last):
  File "/Library/Frameworks/Python.framework/Versions/3.7/lib/python3.7/site-packages/telegram/vendor/ptb_urllib3/urllib3/connectionpool.py", line 617, in urlopen
    chunked=chunked)
  File "/Library/Frameworks/Python.framework/Versions/3.7/lib/python3.7/site-packages/telegram/vendor/ptb_urllib3/urllib3/connectionpool.py", line 402, in _make_request
    six.raise_from(e, None)
  File "<string>", line 2, in raise_from
  File "/Library/Frameworks/Python.framework/Versions/3.7/lib/python3.7/site-packages/telegram/vendor/ptb_urllib3/urllib3/connectionpool.py", line 398, in _make_request
    httplib_response = conn.getresponse()
  File "/Library/Frameworks/Python.framework/Versions/3.7/lib/python3.7/http/client.py", line 1321, in getresponse
    response.begin()
  File "/Library/Frameworks/Python.framework/Versions/3.7/lib/python3.7/http/client.py", line 296, in begin
    version, status, reason = self._read_status()
  File "/Library/Frameworks/Python.framework/Versions/3.7/lib/python3.7/http/client.py", line 257, in _read_status
    line = str(self.fp.readline(_MAXLINE + 1), "iso-8859-1")
  File "/Library/Frameworks/Python.framework/Versions/3.7/lib/python3.7/socket.py", line 589, in readinto
    return self._sock.recv_into(b)
  File "/Library/Frameworks/Python.framework/Versions/3.7/lib/python3.7/ssl.py", line 1052, in recv_into
    return self.read(nbytes, buffer)
  File "/Library/Frameworks/Python.framework/Versions/3.7/lib/python3.7/ssl.py", line 911, in read
    return self._sslobj.read(len, buffer)
ConnectionResetError: [Errno 54] Connection reset by peer

During handling of the above exception, another exception occurred:

Traceback (most recent call last):
  File "/Library/Frameworks/Python.framework/Versions/3.7/lib/python3.7/site-packages/telegram/utils/request.py", line 218, in _request_wrapper
    resp = self._con_pool.request(*args, **kwargs)
  File "/Library/Frameworks/Python.framework/Versions/3.7/lib/python3.7/site-packages/telegram/vendor/ptb_urllib3/urllib3/request.py", line 70, in request
    **urlopen_kw)
  File "/Library/Frameworks/Python.framework/Versions/3.7/lib/python3.7/site-packages/telegram/vendor/ptb_urllib3/urllib3/request.py", line 148, in request_encode_body
    return self.urlopen(method, url, **extra_kw)
  File "/Library/Frameworks/Python.framework/Versions/3.7/lib/python3.7/site-packages/telegram/vendor/ptb_urllib3/urllib3/poolmanager.py", line 244, in urlopen
    response = conn.urlopen(method, u.request_uri, **kw)
  File "/Library/Frameworks/Python.framework/Versions/3.7/lib/python3.7/site-packages/telegram/vendor/ptb_urllib3/urllib3/connectionpool.py", line 666, in urlopen
    _stacktrace=sys.exc_info()[2])
  File "/Library/Frameworks/Python.framework/Versions/3.7/lib/python3.7/site-packages/telegram/vendor/ptb_urllib3/urllib3/util/retry.py", line 347, in increment
    raise six.reraise(type(error), error, _stacktrace)
  File "/Library/Frameworks/Python.framework/Versions/3.7/lib/python3.7/site-packages/telegram/vendor/ptb_urllib3/urllib3/packages/six.py", line 685, in reraise
    raise value.with_traceback(tb)
  File "/Library/Frameworks/Python.framework/Versions/3.7/lib/python3.7/site-packages/telegram/vendor/ptb_urllib3/urllib3/connectionpool.py", line 617, in urlopen
    chunked=chunked)
  File "/Library/Frameworks/Python.framework/Versions/3.7/lib/python3.7/site-packages/telegram/vendor/ptb_urllib3/urllib3/connectionpool.py", line 402, in _make_request
    six.raise_from(e, None)
  File "<string>", line 2, in raise_from
  File "/Library/Frameworks/Python.framework/Versions/3.7/lib/python3.7/site-packages/telegram/vendor/ptb_urllib3/urllib3/connectionpool.py", line 398, in _make_request
    httplib_response = conn.getresponse()
  File "/Library/Frameworks/Python.framework/Versions/3.7/lib/python3.7/http/client.py", line 1321, in getresponse
    response.begin()
  File "/Library/Frameworks/Python.framework/Versions/3.7/lib/python3.7/http/client.py", line 296, in begin
    version, status, reason = self._read_status()
  File "/Library/Frameworks/Python.framework/Versions/3.7/lib/python3.7/http/client.py", line 257, in _read_status
    line = str(self.fp.readline(_MAXLINE + 1), "iso-8859-1")
  File "/Library/Frameworks/Python.framework/Versions/3.7/lib/python3.7/socket.py", line 589, in readinto
    return self._sock.recv_into(b)
  File "/Library/Frameworks/Python.framework/Versions/3.7/lib/python3.7/ssl.py", line 1052, in recv_into
    return self.read(nbytes, buffer)
  File "/Library/Frameworks/Python.framework/Versions/3.7/lib/python3.7/ssl.py", line 911, in read
    return self._sslobj.read(len, buffer)
telegram.vendor.ptb_urllib3.urllib3.exceptions.ProtocolError: ('Connection aborted.', ConnectionResetError(54, 'Connection reset by peer'))

During handling of the above exception, another exception occurred:

Traceback (most recent call last):
  File "/Library/Frameworks/Python.framework/Versions/3.7/lib/python3.7/site-packages/telegram/ext/dispatcher.py", line 372, in process_update
    handler.handle_update(update, self, check, context)
  File "/Library/Frameworks/Python.framework/Versions/3.7/lib/python3.7/site-packages/telegram/ext/handler.py", line 120, in handle_update
    return self.callback(dispatcher.bot, update, **optional_args)
  File "bot.py", line 16, in greet_user
    update.message.reply_text(user_text)
  File "/Library/Frameworks/Python.framework/Versions/3.7/lib/python3.7/site-packages/telegram/message.py", line 478, in reply_text
    return self.bot.send_message(self.chat_id, *args, **kwargs)
  File "/Library/Frameworks/Python.framework/Versions/3.7/lib/python3.7/site-packages/telegram/bot.py", line 66, in decorator
    result = func(self, *args, **kwargs)
  File "/Library/Frameworks/Python.framework/Versions/3.7/lib/python3.7/site-packages/telegram/bot.py", line 258, in send_message
    timeout=timeout, **kwargs)
  File "/Library/Frameworks/Python.framework/Versions/3.7/lib/python3.7/site-packages/telegram/bot.py", line 123, in _message
    result = self._request.post(url, data, timeout=timeout)
  File "/Library/Frameworks/Python.framework/Versions/3.7/lib/python3.7/site-packages/telegram/utils/request.py", line 327, in post
    **urlopen_kwargs)
  File "/Library/Frameworks/Python.framework/Versions/3.7/lib/python3.7/site-packages/telegram/utils/request.py", line 224, in _request_wrapper
    raise NetworkError('urllib3 HTTPError {0}'.format(error))
telegram.error.NetworkError: urllib3 HTTPError ('Connection aborted.', ConnectionResetError(54, 'Connection reset by peer'))
2019-09-11 18:38:39,601 - INFO - Received signal 2 (SIGINT), stopping...
2019-09-11 18:38:48,848 - INFO - Бот запускается.
2019-09-11 18:39:00,558 - INFO - Вызван /start
2019-09-11 18:39:16,060 - INFO - Вызвана /planet
2019-09-11 18:39:29,440 - INFO - Вызвана /planet
2019-09-11 18:39:39,847 - INFO - Вызвана /planet
2019-09-11 18:39:49,440 - INFO - Вызвана /planet
2019-09-12 13:06:27,250 - INFO - Бот запускается.
2019-09-12 13:06:39,239 - INFO - Вызван /start
2019-09-12 13:06:44,250 - INFO - Вызвана /planet
2019-09-12 13:06:50,782 - INFO - Вызвана /planet
